Workbook

Sheet 작성안내
A1: 표준 강의 교안(교과목 운영계획서) 양식 — 작성 안내
A2: 코리아AI아카데미 표준안 v1.0 | 과정평가형·일반 국비(계좌제)·KDT 공통 | 심사·인증 증빙 및 훈련생 안내 겸용
B4: 1. 색상 범례
B5: 노란 배경 + 파란 글씨 | C5: 작성자가 직접 입력하는 칸 (샘플 값이 미리 채워져 있음 → 과목에 맞게 교체)
B6: 회색 배경 | C6: 항목 라벨 — 수정하지 않음
B7: 흰 배경 검정 글씨 | C7: 수식(자동 계산) — 수정하지 않음. 시간 합계·비중 합계·NCS 시간 배분이 자동 계산됨
B8: 연두 배경 | C8: 심사·인증 시 중점 확인 항목 (필수 기재)
B10: 2. 시트 구성과 용도
B11: 시트 | C11: 내용 | D11: 증빙(심사) | E11: 훈련생 안내 | F11: 작성 주체
B12: ① 교과개요 | C12: 교과목 기본정보·훈련유형·목표·강사·교재·장비·결재란 (표지 겸용) | D12: ● | E12: ○ | F12: 교과 담당강사
B13: ② NCS매핑 | C13: NCS 능력단위·요소·수행준거와 차시 연결, 요소별 편성시간 자동 집계 | D13: ● | E13: - | F13: 교과 담당강사
B14: ③ 주차별계획 | C14: 차시별 학습내용·이론/실습 시간·평가 시점·능력단위요소 코드 | D14: ● | E14: ● | F14: 교과 담당강사
B15: ④ 차시별지도안 | C15: 차시별 도입-전개-정리 단계의 교수학습활동·시간·자료·평가 | D15: ● | E15: - | F15: 교과 담당강사
B16: ⑤ 평가계획 | C16: 평가방법·비중·시기, 채점 루브릭, 이수·재평가 기준(유형별) | D16: ● | E16: ● | F16: 담당강사 + 교무
B17: ⑥ 훈련생안내 | C17: 훈련생 배포용 1페이지 요약(목표·준비물·과제·출결·평가·문의) | D17: - | E17: ● | F17: 교무 행정
B19: 3. 작성 원칙
B20: 1. 훈련시간 단위: 1시간 = 50분 수업 + 10분 휴식(기관 규정에 따름). 총 훈련시간은 ③주차별계획의 합계가 기준이며 ①·②·⑥에 자동 반영된다.
B21: 2. 훈련유형별 필수 항목: 과정평가형 → ②NCS매핑 + ⑤능력단위별 내부평가(100점 환산) 필수 / KDT → ⑤프로젝트(실무)평가 및 ③프로젝트 차시 필수 / 일반 국비 → ①·③·⑤ 필수, ②는 NCS 기반 과정일 때 작성.
B22: 3. NCS 코드는 ncs.go.kr에서 최신 버전(예: _20v4)을 확인해 기재하고, 개정 시 코드·버전을 함께 갱신한다.
B23: 4. 차시별지도안은 '실제 수업에서 무엇을 어떻게 했는지'가 드러나야 하며, 현장 모니터링 시 훈련일지·출석부와 대조되므로 ③주차별계획과 차시 번호를 일치시킨다.
B24: 5. 평가 비중 합계는 100%가 되어야 하며(⑤ 자동 검증), 평가 문항·루브릭은 수행준거 문장에서 도출한다.
B25: 6. 훈련생 배포 시에는 ⑥훈련생안내 시트만 PDF로 출력해 전달하고, 심사 제출 시에는 전체 시트를 인쇄한다(각 시트 A4 가로 인쇄 설정 완료).
B27: 4. 참고 근거
B28: 과정평가형 이수기준: 능력단위별 출석률 75% 이상 + 모든 내부평가 참여, 능력단위별 100점 환산, 지필·실무평가 병행, 내·외부평가 1:1 반영 평균 80점 이상 합격 [출처: 큐넷 과정평가형자격 운영절차 c.q-net.or.kr]
B29: NCS 분류: 20.정보통신 > 01.정보기술 > 02.정보기술개발 > 03.응용SW엔지니어링 > 프로그래밍 언어 활용(2001020215_20v4) — 세부 코드·버전은 ncs.go.kr에서 최종 확인 필요 [출처: NCS 국가직무능력표준 ncs.go.kr]
B30: KDT 심사: 훈련내용의 실무·프로젝트 중심 구성, 강사 요건(선도기업 아카데미의 경우 현직자 참여 80% 이상), 취업률(수료 6개월 후 산정) 등을 종합 심사 [출처: 대한민국 정책브리핑 korea.kr]

Sheet 교과개요
A1: 강의 교안 (교과목 운영계획서)
A2: 훈련기관: 코리아AI아카데미 | 문서번호: KAA-LP-2026-PY01 | 작성일: 2026-09-09
A4: 1. 교과목 기본 정보 | F4: 결재 | G4: 담당강사 | H4: 교무팀장
A5: 훈련과정명 | B5: AI 융합 파이썬 백엔드 개발자 양성과정 (예시) | C5: 훈련유형 | D5: ☑ 과정평가형 ☑ 일반국비(계좌제) ☑ KDT | G5: (서명) | H5: (서명)
A6: 교과목명 | B6: 파이썬 프로그래밍 기초 | C6: 교과목 코드 | D6: PY-101 | G6: 결재일: . .
A7: 훈련기간 | B7: 2026-10-05 ~ 2026-10-16 (2주, 10일) | C7: 교육시간 | D7: 월~금 09:00 ~ 13:00 (1일 4시간) | F7: 부원장 | G7: (서명)
A8: 담당강사 | B8: 홍길동 (정보처리기사, 파이썬 실무 8년) | C8: 보조강사/멘토 | D8: 김멘토 (실습 보조, 과제 피드백)
A9: 훈련장소 | B9: 본원 3층 실습실 A (PC 25대) | C9: 정원 | D9: 20명
A10: 총 훈련시간 | B10: =주차별계획!$H$26 -> 40 | C10: 이론 / 실습 | D10: =주차별계획!$F$26&"시간 / "&주차별계획!$G$26&"시간" -> 12.5시간 / 27.5시간
A11: 평가 시간(포함) | B11: =평가계획!$D$13 -> 2 | C11: 실습 비율 | D11: =IF(주차별계획!$H$26=0,0,주차별계획!$G$26/주차별계획!$H$26) -> 0.6875
A13: 2. NCS 분류 및 능력단위
A14: NCS 분류 | B14: 20.정보통신 > 01.정보기술 > 02.정보기술개발 > 03.응용SW엔지니어링 | E14: 능력단위(코드) | F14: 프로그래밍 언어 활용 (2001020215_20v4) — 수준 3
A15: 능력단위요소 | B15: ① 기본문법 활용하기 ② 언어특성 활용하기 ③ 라이브러리 활용하기 (요소별 편성시간은 ②NCS매핑 시트 자동 집계)
A17: 3. 교육 목표 및 내용
A18: 교과 목표(총괄) | B18: 파이썬의 기본 문법과 언어 특성을 이해하고, 표준·외부 라이브러리를 활용하여 데이터 처리 및 소규모 응용 프로그램을 독립적으로 설계·구현·발표할 수 있다.
A19: 세부 학습목표 | B19: 1) 변수·자료형·연산자·제어문·자료구조·함수를 활용하여 요구사항에 맞는 프로그램을 작성할 수 있다. (요소①)
B20: 2) 모듈화, 예외처리, 객체지향(클래스·상속) 등 파이썬의 언어 특성을 적용하여 유지보수 가능한 코드를 작성할 수 있다. (요소②)
B21: 3) 표준 라이브러리와 외부 패키지(pandas, matplotlib 등)를 검색·설치·활용하여 파일 및 데이터를 처리하고 시각화할 수 있다. (요소③)
B22: 4) 팀 단위 미니 프로젝트를 기획·구현·발표하고 Git으로 산출물을 관리할 수 있다. (KDT 프로젝트 역량)
A23: 선수학습/입과요건 | B23: 컴퓨터 기본 조작 가능자. 프로그래밍 경험 불필요(입과 전 사전 진단 테스트 실시, 미달자는 사전 학습 자료 제공)
A24: 교수학습 방법 | B24: 이론 강의(30%) + 라이브 코딩 실습(50%) + 팀 프로젝트/발표(20%). 매 차시 실습 과제, 격주 형성평가, 종료 시 능력단위 내부평가
A26: 4. 교재·장비·자료
A27: 주교재 | B27: 자체 제작 교안(PDF) + 실습 노트북(Jupyter) | E27: 부교재/참고 | F27: 파이썬 공식 문서 docs.python.org, NCS 학습모듈 '프로그래밍 언어 활용'
A28: SW/개발환경 | B28: Python 3.12, VS Code, Jupyter, Git/GitHub, pandas, matplotlib | E28: HW/장비 | F28: 실습용 PC 25대(8GB↑), 빔프로젝터, 전자칠판, 화이트보드
A29: LMS/소통 채널 | B29: 기관 LMS(과제 제출·출결), 슬랙 채널(질의응답, 공지)
A31: 5. 평가 개요 (상세는 ⑤평가계획)
A32: 평가 방법 | B32: =평가계획!$B$7&" "&TEXT(평가계획!$C$7,"0%")&" / "&평가계획!$B$8&" "&TEXT(평가계획!$C$8,"0%")&" / "&평가계획!$B$9&" "&TEXT(평가계획!$C$9,"0%")&" / "&평가계획!$B$10&" "&TEXT(평가계획!$C$10,"0%") -> 형성평가(퀴즈) 10% / 실습과제 30% / 지필평가 20% / 실무평가(프로젝트) 40%
A33: 이수 기준 | B33: 출석률 80% 이상(과정평가형: 능력단위별 75% 이상) + 모든 내부평가 참여 + 종합 60점 이상. 능력단위별 100점 환산 성적을 별도 산출
A35: 비고/특이사항 | B35: 본 교과 종료 후 '웹 백엔드(Django)' 교과로 연계. 프로젝트 산출물은 GitHub 저장소 링크로 제출·보관(증빙용).

Sheet NCS매핑
A1: ② NCS 능력단위 매핑표
A2: 능력단위: 프로그래밍 언어 활용 (2001020215_20v4) | 요소별 편성시간은 ③주차별계획의 'NCS요소' 열에서 자동 집계 | 코드·버전은 ncs.go.kr에서 최종 확인
A4: 능력단위요소(코드) | B4: 수행준거 번호 | C4: 수행준거 (NCS 원문 기준으로 기재) | D4: 연계 차시 | E4: 편성시간(h) | F4: 비율 | G4: 평가 방법 | H4: 평가 차시
A5: 기본문법 활용하기 (2001020215_20v4.1) | B5: 1.1 | C5: 응용소프트웨어 개발에 필요한 프로그래밍 언어의 데이터 타입, 변수, 연산자를 활용하여 프로그램을 작성할 수 있다. | D5: 1~7차시 | E5: =SUMIF(주차별계획!$J$5:$J$24,"2001020215_20v4.1",주차별계획!$H$5:$H$24) -> 14 | F5: =IF($E$22=0,0,E5/$E$22) -> 0.35 | G5: 형성평가①, 실습과제 | H5: 7차시
B6: 1.2 | C6: 조건문·반복문 등 제어문을 활용하여 프로그램의 흐름을 구성할 수 있다.
B7: 1.3 | C7: 배열(리스트)·딕셔너리 등 자료구조를 활용하여 데이터를 저장·처리할 수 있다.
A8: 언어특성 활용하기 (2001020215_20v4.2) | B8: 2.1 | C8: 함수·프로시저를 정의하고 매개변수와 반환값을 활용하여 모듈화된 프로그램을 작성할 수 있다. | D8: 8~9, 11, 13~14차시 | E8: =SUMIF(주차별계획!$J$5:$J$24,"2001020215_20v4.2",주차별계획!$H$5:$H$24) -> 10 | F8: =IF($E$22=0,0,E8/$E$22) -> 0.25 | G8: 형성평가②, 실습과제 | H8: 14차시
B9: 2.2 | C9: 예외처리 기법을 적용하여 오류에 안정적인 프로그램을 작성할 수 있다.
B10: 2.3 | C10: 객체지향 언어의 클래스·상속·다형성 특성을 활용하여 프로그램을 작성할 수 있다.
A11: 라이브러리 활용하기 (2001020215_20v4.3) | B11: 3.1 | C11: 표준 라이브러리를 검색·활용하여 프로그램에 필요한 기능을 구현할 수 있다. | D11: 10, 12, 15~17차시 | E11: =SUMIF(주차별계획!$J$5:$J$24,"2001020215_20v4.3",주차별계획!$H$5:$H$24) -> 10 | F11: =IF($E$22=0,0,E11/$E$22) -> 0.25 | G11: 실습과제, 지필평가 | H11: 20차시
B12: 3.2 | C12: 외부 라이브러리를 설치·활용하여 파일·데이터 처리 및 시각화 기능을 구현할 수 있다.
A13: 종합(프로젝트) 요소 ①②③ 통합 | B13: P | C13: 요구사항을 분석하고 기본문법·언어특성·라이브러리를 종합 활용하여 소규모 응용 프로그램을 구현·발표할 수 있다. | D13: 18~20차시 | E13: =SUMIF(주차별계획!$J$5:$J$24,"프로젝트(①②③)",주차별계획!$H$5:$H$24) -> 6 | F13: =IF($E$22=0,0,E13/$E$22) -> 0.15 | G13: 실무평가(프로젝트), 지필평가 | H13: 20차시
A22: 합계 | E22: =E5+E8+E11+E13 -> 40 | F22: =F5+F8+F11+F13 -> 1 | G22: =IF(E22=주차별계획!H25,"✔ 주차별계획 총시간과 일치","⚠ 미매핑 차시 존재") -> ✔ 주차별계획 총시간과 일치
A24: ※ 수행준거 문장은 NCS 포털(ncs.go.kr)의 능력단위 원문을 그대로 옮겨 적는다. 위 문장은 샘플용 요약본이며, 심사 제출 전 원문·버전으로 교체할 것. 과정평가형은 능력단위별 편성시간과 내부평가 시기가 편성기준과 일치해야 한다.

Sheet 주차별계획
A1: ③ 주차별·차시별 훈련 계획
A2: 교과목: 파이썬 프로그래밍 기초 | 총 40시간 (10일 × 4시간, 1일 2차시 × 2시간) | 평가 차시는 훈련시간에 포함
A4: 일차 | B4: 차시 | C4: 단원(대주제) | D4: 학습내용(소주제·활동) | E4: 이론(h) | F4: 실습(h) | G4: 평가(h) | H4: 소계(h) | I4: 평가/과제 | J4: NCS요소
A5: 1 | B5: 1 | C5: 파이썬 개요·개발환경 | D5: 파이썬 특징과 활용 분야, Python/VS Code/Jupyter 설치, 첫 프로그램 실행, Git 계정 생성 | E5: 1 | F5: 1 | G5: 0 | H5: =SUM(E5:G5) -> 2 | J5: 2001020215_20v4.1
A6: 1 | B6: 2 | C6: 변수와 자료형 | D6: 변수·상수, 숫자/문자열/불리언, 형변환, 산술·비교·논리 연산자, 입출력(input/print) | E6: 1 | F6: 1 | G6: 0 | H6: =SUM(E6:G6) -> 2 | J6: 2001020215_20v4.1
A7: 2 | B7: 3 | C7: 문자열 처리 | D7: 인덱싱·슬라이싱, 문자열 메서드, f-string 포매팅, 이스케이프 | E7: 0.5 | F7: 1.5 | G7: 0 | H7: =SUM(E7:G7) -> 2 | J7: 2001020215_20v4.1
A8: 2 | B8: 4 | C8: 조건문 | D8: if/elif/else, 중첩 조건, 논리 연산 결합, 조건식 활용 실습(성적 계산기) | E8: 0.5 | F8: 1.5 | G8: 0 | H8: =SUM(E8:G8) -> 2 | J8: 2001020215_20v4.1
A9: 3 | B9: 5 | C9: 반복문 | D9: for/while, range, break/continue, 중첩 반복, 패턴 출력 실습 | E9: 0.5 | F9: 1.5 | G9: 0 | H9: =SUM(E9:G9) -> 2 | J9: 2001020215_20v4.1
A10: 3 | B10: 6 | C10: 리스트와 튜플 | D10: 리스트 생성·수정·메서드, 튜플, 리스트 컴프리헨션, 정렬 | E10: 0.5 | F10: 1.5 | G10: 0 | H10: =SUM(E10:G10) -> 2 | J10: 2001020215_20v4.1
A11: 4 | B11: 7 | C11: 딕셔너리와 집합 | D11: key-value 구조, 딕셔너리 메서드, 집합 연산, 자료구조 선택 기준 | E11: 0.5 | F11: 1.5 | G11: 0 | H11: =SUM(E11:G11) -> 2 | I11: 형성평가① | J11: 2001020215_20v4.1
A12: 4 | B12: 8 | C12: 함수 기초 | D12: 함수 정의·호출, 매개변수·반환값, 기본값·가변 인자, 독스트링 | E12: 1 | F12: 1 | G12: 0 | H12: =SUM(E12:G12) -> 2 | J12: 2001020215_20v4.2
A13: 5 | B13: 9 | C13: 함수 심화 | D13: 스코프(global/nonlocal), 람다, 재귀, 고차함수(map/filter), 타입 힌트 | E13: 1 | F13: 1 | G13: 0 | H13: =SUM(E13:G13) -> 2 | J13: 2001020215_20v4.2
A14: 5 | B14: 10 | C14: 모듈과 패키지 | D14: import 구조, 표준 라이브러리(math, random, datetime, os), 사용자 모듈 작성 | E14: 0.5 | F14: 1.5 | G14: 0 | H14: =SUM(E14:G14) -> 2 | J14: 2001020215_20v4.3
A15: 6 | B15: 11 | C15: 예외 처리 | D15: try/except/else/finally, 예외 계층, 사용자 정의 예외, 방어적 코딩 | E15: 1 | F15: 1 | G15: 0 | H15: =SUM(E15:G15) -> 2 | J15: 2001020215_20v4.2
A16: 6 | B16: 12 | C16: 파일 입출력 | D16: 텍스트/CSV/JSON 읽기·쓰기, with 문, 인코딩, 로그 파일 처리 실습 | E16: 0.5 | F16: 1.5 | G16: 0 | H16: =SUM(E16:G16) -> 2 | J16: 2001020215_20v4.3
A17: 7 | B17: 13 | C17: 클래스와 객체 | D17: 클래스 정의, __init__, 인스턴스/클래스 변수, 메서드, 캡슐화 | E17: 1 | F17: 1 | G17: 0 | H17: =SUM(E17:G17) -> 2 | J17: 2001020215_20v4.2
A18: 7 | B18: 14 | C18: 상속과 다형성 | D18: 상속, 메서드 오버라이딩, super(), 특수 메서드(__str__, __len__), 객체지향 설계 실습 | E18: 1 | F18: 1 | G18: 0 | H18: =SUM(E18:G18) -> 2 | I18: 형성평가② | J18: 2001020215_20v4.2
A19: 8 | B19: 15 | C19: 외부 라이브러리 활용 | D19: pip·가상환경(venv), requests로 공개 API 호출, 패키지 문서 읽는 법 | E19: 0.5 | F19: 1.5 | G19: 0 | H19: =SUM(E19:G19) -> 2 | J19: 2001020215_20v4.3
A20: 8 | B20: 16 | C20: 데이터 처리(pandas 기초) | D20: DataFrame 생성·조회·필터·집계, CSV 데이터 정제 실습 | E20: 0.5 | F20: 1.5 | G20: 0 | H20: =SUM(E20:G20) -> 2 | J20: 2001020215_20v4.3
A21: 9 | B21: 17 | C21: 데이터 시각화 | D21: matplotlib 기본 차트(막대·선·산점도), 제목·축·범례, 결과 저장 | E21: 0.5 | F21: 1.5 | G21: 0 | H21: =SUM(E21:G21) -> 2 | J21: 2001020215_20v4.3
A22: 9 | B22: 18 | C22: 미니 프로젝트 기획·설계 | D22: 팀 편성, 주제 선정(공공데이터 분석/간단 CLI 앱), 요구사항·기능 명세, Git 저장소 구성 | E22: 0.5 | F22: 1.5 | G22: 0 | H22: =SUM(E22:G22) -> 2 | J22: 프로젝트(①②③)
A23: 10 | B23: 19 | C23: 미니 프로젝트 구현 | D23: 기능 구현, 코드 리뷰, 예외처리·리팩토링, README 작성 | E23: 0 | F23: 2 | G23: 0 | H23: =SUM(E23:G23) -> 2 | J23: 프로젝트(①②③)
A24: 10 | B24: 20 | C24: 프로젝트 발표 및 내부평가 | D24: 팀별 발표(10분)·피드백, 지필평가(40분), 실무평가(코딩 과제 60분) | E24: 0 | F24: 0 | G24: 2 | H24: =SUM(E24:G24) -> 2 | I24: 지필+실무평가 | J24: 프로젝트(①②③)
A25: 합계 (총 훈련시간) | E25: =SUM(E5:E24) -> 12.5 | F25: =SUM(F5:F24) -> 25.5 | G25: =SUM(G5:G24) -> 2 | H25: =SUM(H5:H24) -> 40 | I25: =IF(H25=40,"✔ 계획시간 일치","⚠ 계획 40h와 불일치") -> ✔ 계획시간 일치
A26: 분류 집계 → 이론 / 실습(평가 포함) / 총계 | F26: =E25 -> 12.5 | G26: =F25+G25 -> 27.5 | H26: =H25 -> 40 | I26: ※ 실습 비율 = G26/H26
A28: ※ 작성 요령: 차시 번호는 ④차시별지도안·훈련일지와 동일하게 유지. 평가(h)는 평가 실시 시간만 기재(훈련시간 포함). NCS요소 열은 능력단위요소 코드 또는 '프로젝트'로 표기하며 ②NCS매핑에서 자동 집계됨.

Sheet 차시별지도안
A1: ④ 차시별 상세 지도안
A2: 차시 = 2시간(120분: 50분 수업 + 10분 휴식 × 2) | 도입 → 전개 → 정리 | ③주차별계획과 차시 번호 일치
A4: 차시 | B4: 학습주제 / 학습목표 | C4: 단계 | D4: 시간(분) | E4: 교수·학습 활동 (강사 ↔ 훈련생) | F4: 교수자료·도구 | G4: 평가·과제 | H4: 비고
A5: 1 | B5: 파이썬 개요와 개발환경 구축 / 개발환경을 설치하고 첫 프로그램을 실행할 수 있다. | C5: 도입 | D5: 15 | E5: 오리엔테이션(교과 목표·평가·출결 안내), 파이썬 활용 사례 소개, 사전 진단 결과 공유 | F5: 교과개요, 훈련생안내 시트, 사례 영상
C6: 전개 | D6: 90 | E6: [강사] Python·VS Code·Jupyter 설치 시연 → [훈련생] 개별 설치, print('Hello') 실행, Git 계정 생성 → [강사] 순회 점검·오류 해결 | F6: 설치 가이드 PDF, 체크리스트
C7: 정리 | D7: 15 | E7: 설치 체크리스트 제출, 다음 차시 예고 | F7: LMS 체크리스트 | G7: 체크리스트
C8: 소계 | D8: =SUM(D5:D7) -> 120 | E8: =IF(D8=120,"✔ 120분(2h) 구성","⚠ 시간 배분 확인 필요") -> ✔ 120분(2h) 구성
A9: 2 | B9: 변수와 자료형, 연산자 / 변수와 기본 자료형을 선언하고 연산자로 값을 계산할 수 있다. | C9: 도입 | D9: 15 | E9: 전 차시 복습 퀴즈(3문항), 일상 속 데이터 유형 예시로 자료형 동기 유발 | F9: 슬라이드, 퀴즈(멘티미터)
C10: 전개 | D10: 90 | E10: [강사] 변수·자료형·형변환·연산자 라이브 코딩 → [훈련생] 따라하기 → 실습: BMI 계산기, 거스름돈 계산 → 페어 코드 리뷰 | F10: 실습 노트북 02, 실습 문제지
C11: 정리 | D11: 15 | E11: 핵심 정리, 실습과제 02(온도 변환기) 공지 | F11: LMS 과제 | G11: 실습과제 02 (LMS 제출)
C12: 소계 | D12: =SUM(D9:D11) -> 120 | E12: =IF(D12=120,"✔ 120분(2h) 구성","⚠ 시간 배분 확인 필요") -> ✔ 120분(2h) 구성
A13: 3 | B13: 문자열 처리 / 문자열 메서드와 포매팅으로 텍스트를 가공할 수 있다. | C13: 도입 | D13: 15 | E13: 과제 02 우수 코드 공유, 문자열 처리 실무 사례(로그·이름 정제) | F13: 과제 피드백 자료
C14: 전개 | D14: 90 | E14: [강사] 인덱싱·슬라이싱·메서드·f-string 시연 → [훈련생] 실습: 이메일 도메인 추출, 주민번호 마스킹, 문자열 역순 판별 | F14: 실습 노트북 03
C15: 정리 | D15: 15 | E15: 정리 퀴즈, 실습과제 03 공지 | F15: LMS 과제 | G15: 실습과제 03 (LMS 제출)
C16: 소계 | D16: =SUM(D13:D15) -> 120 | E16: =IF(D16=120,"✔ 120분(2h) 구성","⚠ 시간 배분 확인 필요") -> ✔ 120분(2h) 구성
A17: 4 | B17: 조건문 / 조건에 따라 프로그램 흐름을 분기할 수 있다. | C17: 도입 | D17: 15 | E17: 순서도로 분기 개념 소개, '성적 등급 판정' 문제 제시 | F17: 순서도 슬라이드
C18: 전개 | D18: 90 | E18: [강사] if/elif/else·중첩·논리 결합 시연 → [훈련생] 실습: 성적 계산기, 윤년 판별, 로그인 검증 → 코드 리뷰 | F18: 실습 노트북 04
C19: 정리 | D19: 15 | E19: 자주 하는 실수(들여쓰기·비교연산) 정리, 과제 04 공지 | F19: LMS 과제 | G19: 실습과제 04 (LMS 제출)
C20: 소계 | D20: =SUM(D17:D19) -> 120 | E20: =IF(D20=120,"✔ 120분(2h) 구성","⚠ 시간 배분 확인 필요") -> ✔ 120분(2h) 구성
A21: 5 | B21: 반복문 / 반복문으로 반복 작업을 자동화할 수 있다. | C21: 도입 | D21: 15 | E21: 반복 자동화 사례(엑셀 반복작업 대체) 소개 | F21: 사례 슬라이드
C22: 전개 | D22: 90 | E22: [강사] for/while·range·break/continue·중첩 반복 시연 → [훈련생] 실습: 구구단, 별 패턴, 소수 찾기, 숫자 맞히기 게임 | F22: 실습 노트북 05
C23: 정리 | D23: 15 | E23: 정리 퀴즈, 과제 05 공지 | F23: LMS 과제 | G23: 실습과제 05 (LMS 제출)
C24: 소계 | D24: =SUM(D21:D23) -> 120 | E24: =IF(D24=120,"✔ 120분(2h) 구성","⚠ 시간 배분 확인 필요") -> ✔ 120분(2h) 구성
A25: 6 | B25: 리스트와 튜플 / 리스트를 생성·수정하고 컴프리헨션으로 처리할 수 있다. | C25: 도입 | D25: 15 | E25: 여러 값을 하나의 변수로 관리해야 하는 상황 제시 | F25: 슬라이드
C26: 전개 | D26: 90 | E26: [강사] 리스트 메서드·슬라이싱·정렬·컴프리헨션 시연 → [훈련생] 실습: 성적 통계, 중복 제거, 장바구니 프로그램 | F26: 실습 노트북 06
C27: 정리 | D27: 15 | E27: 리스트 vs 튜플 비교 정리, 과제 06 공지 | F27: LMS 과제 | G27: 실습과제 06 (LMS 제출)
C28: 소계 | D28: =SUM(D25:D27) -> 120 | E28: =IF(D28=120,"✔ 120분(2h) 구성","⚠ 시간 배분 확인 필요") -> ✔ 120분(2h) 구성
A29: 7 | B29: 딕셔너리와 집합 / 상황에 맞는 자료구조를 선택해 데이터를 처리할 수 있다. | C29: 도입 | D29: 15 | E29: 형성평가① 안내(범위: 1~7차시) | F29: 평가 안내문
C30: 전개 | D30: 90 | E30: [강사] 딕셔너리·집합 연산 시연 → [훈련생] 실습: 단어 빈도 세기, 학생 명부 관리 → 형성평가①(객관식 10문항 + 코딩 2문항, 40분) | F30: 실습 노트북 07, 형성평가① 문항 | G30: 형성평가① 5%
C31: 정리 | D31: 15 | E31: 평가 결과 즉시 피드백, 자료구조 선택 기준 정리 | F31: 평가 결과표
C32: 소계 | D32: =SUM(D29:D31) -> 120 | E32: =IF(D32=120,"✔ 120분(2h) 구성","⚠ 시간 배분 확인 필요") -> ✔ 120분(2h) 구성
A33: 8 | B33: 함수 기초 / 함수를 정의·호출하고 매개변수와 반환값을 활용할 수 있다. | C33: 도입 | D33: 15 | E33: 형성평가① 오답 해설, 반복 코드의 문제점 제시 | F33: 오답 해설 자료
C34: 전개 | D34: 90 | E34: [강사] 함수 정의·호출·기본값·가변인자·독스트링 시연 → [훈련생] 실습: 계산기 함수, 성적 처리 함수 리팩토링 | F34: 실습 노트북 08
C35: 정리 | D35: 15 | E35: 정리, 과제 08 공지 | F35: LMS 과제 | G35: 실습과제 08 (LMS 제출)
C36: 소계 | D36: =SUM(D33:D35) -> 120 | E36: =IF(D36=120,"✔ 120분(2h) 구성","⚠ 시간 배분 확인 필요") -> ✔ 120분(2h) 구성
A37: 9 | B37: 함수 심화 / 스코프·람다·재귀·고차함수를 활용할 수 있다. | C37: 도입 | D37: 15 | E37: 전 차시 과제 코드 리뷰 | F37: 과제 코드
C38: 전개 | D38: 90 | E38: [강사] global/nonlocal·람다·재귀·map/filter·타입 힌트 시연 → [훈련생] 실습: 팩토리얼·피보나치, 정렬 키 함수, 데이터 필터링 | F38: 실습 노트북 09
C39: 정리 | D39: 15 | E39: 정리 퀴즈, 과제 09 공지 | F39: LMS 과제 | G39: 실습과제 09 (LMS 제출)
C40: 소계 | D40: =SUM(D37:D39) -> 120 | E40: =IF(D40=120,"✔ 120분(2h) 구성","⚠ 시간 배분 확인 필요") -> ✔ 120분(2h) 구성
A41: 10 | B41: 모듈과 패키지 / 표준 라이브러리와 사용자 모듈을 활용할 수 있다. | C41: 도입 | D41: 15 | E41: '바퀴를 다시 만들지 말라' — 라이브러리 활용 동기 부여 | F41: 슬라이드
...

Sheet 평가계획
A1: ⑤ 평가 계획 (내부평가)
A2: 평가 비중 합계 100% 자동 검증 | 과정평가형: 능력단위별 100점 환산 · 지필/실무 병행 · 평가시간은 훈련시간에 포함 | KDT: 프로젝트(실무)평가 중심
A4: 1. 평가 방법 및 비중
A6: No | B6: 평가 방법 | C6: 비중 | D6: 평가시간(h) | E6: 시기(차시) | F6: 평가 내용·문항 구성 | G6: 평가 대상 능력단위요소 | H6: 평가 도구/증빙
A7: 1 | B7: 형성평가(퀴즈) | C7: 0.1 | D7: 0 | E7: 7·14차시 | F7: 객관식 10문항 + 코딩 2문항 × 2회 (각 5%), 40분, 수업 중 실시 | G7: 요소①(7차시), 요소②(14차시) | H7: 평가지, 답안, 결과표
A8: 2 | B8: 실습과제 | C8: 0.3 | D8: 0 | E8: 매 차시 | F8: 차시별 LMS 제출 과제 15건, 체크리스트 채점(제출·동작·코드품질) | G8: 요소①②③ | H8: LMS 제출 기록, 채점표
A9: 3 | B9: 지필평가 | C9: 0.2 | D9: 1 | E9: 20차시 | F9: 객관식 20문항 + 단답 5문항 + 코드 해석 5문항, 40분 | G9: 요소①②③ 전체 | H9: 평가지, 답안지, 성적표
A10: 4 | B10: 실무평가(프로젝트) | C10: 0.4 | D10: 1 | E10: 18~20차시 | F10: 팀 프로젝트 산출물(설계서·코드·README) + 발표 + 개인 코딩 과제(60분), 루브릭 채점 | G10: 요소①②③ 통합 | H10: GitHub 링크, 발표자료, 루브릭 채점표
A11: 합계 | C11: =SUM(C7:C10) -> 1 | D11: =SUM(D7:D10) -> 2 | E11: =IF(ROUND(C11,4)=1,"✔ 비중 합계 100%","⚠ 비중 합계가 100%가 아님") -> ✔ 비중 합계 100%
A13: 평가 시간 합계(훈련시간 포함) → | D13: =D11 -> 2 | E13: =IF(D13=주차별계획!G25,"✔ 주차별계획 평가시간과 일치","⚠ 주차별계획의 평가(h) 열과 불일치") -> ✔ 주차별계획 평가시간과 일치
A15: 2. 실무평가(프로젝트) 채점 루브릭
A16: No | B16: 평가 항목 | C16: 배점 | D16: 우수(90~100%) | E16: 보통(70~89%) | F16: 미흡(~69%) | G16: 관련 수행준거 | H16: 채점 근거
A17: 1 | B17: 요구사항 분석·설계 | C17: 15 | D17: 요구사항·기능 명세가 명확하고 설계서와 구현이 일치 | E17: 명세는 있으나 일부 기능 누락·불일치 | F17: 설계서 미흡 또는 미제출 | G17: P | H17: 설계서
A18: 2 | B18: 기본문법·자료구조 활용 | C18: 20 | D18: 적절한 자료구조·제어문을 선택, 오류 없이 동작 | E18: 동작하나 비효율적 구조·일부 오류 | F18: 핵심 기능 미동작 | G18: 1.1~1.3 | H18: 코드
A19: 3 | B19: 함수화·객체지향·예외처리 | C19: 20 | D19: 기능이 함수/클래스로 모듈화되고 예외처리가 적용됨 | E19: 일부만 모듈화, 예외처리 제한적 | F19: 단일 스크립트, 예외처리 없음 | G19: 2.1~2.3 | H19: 코드
A20: 4 | B20: 라이브러리 활용·데이터 처리 | C20: 15 | D20: 표준·외부 라이브러리를 목적에 맞게 활용, 결과 정확 | E20: 라이브러리 사용은 하나 활용도 낮음 | F20: 라이브러리 미활용 | G20: 3.1~3.2 | H20: 코드·실행결과
A21: 5 | B21: 코드 품질·문서화(README·Git) | C21: 10 | D21: 명명·주석·README 충실, 커밋 이력 규칙적 | E21: README 있으나 미흡, 커밋 불규칙 | F21: 문서·이력 없음 | G21: P | H21: GitHub
A22: 6 | B22: 발표·협업 | C22: 10 | D22: 역할 분담 명확, 발표 논리적, 질의응답 적절 | E22: 발표는 하나 역할·근거 불명확 | F22: 발표 미참여 | G22: P | H22: 발표·관찰
A23: 7 | B23: 개인 코딩 과제(60분) | C23: 10 | D23: 요구 기능 전부 구현·테스트 통과 | E23: 일부 구현 | F23: 미구현 | G23: 1~3 종합 | H23: 제출 코드
A24: 배점 합계 | C24: =SUM(C17:C23) -> 100 | D24: =IF(C24=100,"✔ 100점 만점","⚠ 배점 합계 확인") -> ✔ 100점 만점
A26: 3. 이수·재평가 기준 (훈련유형별)
B27: 훈련유형 | C27: 출석 기준 | E27: 성적 기준 | F27: 재평가/보충 | G27: 성적 산출 | H27: 근거
B28: 과정평가형 | C28: 능력단위별 출석률 75% 이상 | E28: 능력단위별 100점 환산, 모든 내부평가 참여 필수 | F28: 미참여·미달 시 1회 재평가(동일 난이도 대체 문항), 재평가 결과로 대체 | G28: 내부평가 성적은 외부평가와 1:1 반영, 평균 80점 이상 합격 | H28: 큐넷 과정평가형 운영절차
B29: 일반 국비(계좌제) | C29: 교과 출석률 80% 이상 (과정 전체 기준 준용) | E29: 종합 60점 이상 | F29: 60점 미만 시 보충학습 후 재평가 1회 | G29: 가중 합산 100점 만점, 수료 시 성적증명 발급 | H29: 기관 학칙·훈련규정
B30: KDT | C30: 교과 출석률 80% 이상 | E30: 프로젝트(실무)평가 필수 참여, 종합 60점 이상 | F30: 프로젝트 미제출 시 개인 과제로 대체 평가 | G30: 역량 진단 결과와 함께 훈련생 포트폴리오에 반영 | H30: 기관 KDT 운영계획
A32: ※ 능력단위별 100점 환산 예시: 요소① = (형성평가① + 관련 실습과제 + 지필 해당 문항 + 루브릭 항목2) 득점 합 ÷ 만점 × 100. 산출식은 교무와 협의해 확정하고 성적표 양식에 명시한다.

Sheet 훈련생안내
A1: ⑥ 훈련생 안내문 — 파이썬 프로그래밍 기초
A2: 이 페이지만 인쇄/PDF로 배포합니다. 기본 정보는 다른 시트에서 자동으로 가져옵니다.
A4: 1. 교과 기본 정보
A5: 훈련과정 | B5: =교과개요!B5 -> AI 융합 파이썬 백엔드 개발자 양성과정 (예시) | C5: 교과목 | D5: =교과개요!B6 -> 파이썬 프로그래밍 기초
A6: 훈련기간 | B6: =교과개요!B7 -> 2026-10-05 ~ 2026-10-16 (2주, 10일) | C6: 교육시간 | D6: =교과개요!D7 -> 월~금 09:00 ~ 13:00 (1일 4시간)
A7: 담당강사 | B7: =교과개요!B8 -> 홍길동 (정보처리기사, 파이썬 실무 8년) | C7: 보조강사/멘토 | D7: =교과개요!D8 -> 김멘토 (실습 보조, 과제 피드백)
A8: 강의실 | B8: =교과개요!B9 -> 본원 3층 실습실 A (PC 25대) | C8: 총 훈련시간 | D8: =주차별계획!H25&"시간 (이론 "&주차별계획!F26&"h / 실습 "&주차별계획!G26&"h)" -> 40시간 (이론 12.5h / 실습 27.5h)
A10: 2. 이 교과를 마치면
A11: =교과개요!B19 -> 1) 변수·자료형·연산자·제어문·자료구조·함수를 활용하여 요구사항에 맞는 프로그램을 작성할 수 있다. (요소①)
A12: =교과개요!B20 -> 2) 모듈화, 예외처리, 객체지향(클래스·상속) 등 파이썬의 언어 특성을 적용하여 유지보수 가능한 코드를 작성할 수 있다. (요소②)
A13: =교과개요!B21 -> 3) 표준 라이브러리와 외부 패키지(pandas, matplotlib 등)를 검색·설치·활용하여 파일 및 데이터를 처리하고 시각화할 수 있다. (요소③)
A14: =교과개요!B22 -> 4) 팀 단위 미니 프로젝트를 기획·구현·발표하고 Git으로 산출물을 관리할 수 있다. (KDT 프로젝트 역량)
A16: 3. 준비물 및 학습 환경
A17: 준비물 | B17: 개인 노트북 지참 권장(없을 경우 실습실 PC 사용), USB 또는 클라우드 저장공간, 필기도구
A18: 사전 설치 | B18: Python 3.12, VS Code, GitHub 계정 — 1차시에 함께 설치하므로 미리 못 해도 괜찮습니다
A19: 소통 채널 | B19: =교과개요!B29 -> 기관 LMS(과제 제출·출결), 슬랙 채널(질의응답, 공지)
A21: 4. 수업 진행 순서 (요약)
A22: 일차 | B22: 오전 1교시(차시·주제) | C22: 일차 | D22: 오전 2교시(차시·주제)
A23: 1일차 | B23: =주차별계획!B5&"차시 "&주차별계획!C5 -> 1차시 파이썬 개요·개발환경 | C23: 1일차 | D23: =주차별계획!B6&"차시 "&주차별계획!C6 -> 2차시 변수와 자료형
A24: 2일차 | B24: =주차별계획!B7&"차시 "&주차별계획!C7 -> 3차시 문자열 처리 | C24: 2일차 | D24: =주차별계획!B8&"차시 "&주차별계획!C8 -> 4차시 조건문
A25: 3일차 | B25: =주차별계획!B9&"차시 "&주차별계획!C9 -> 5차시 반복문 | C25: 3일차 | D25: =주차별계획!B10&"차시 "&주차별계획!C10 -> 6차시 리스트와 튜플
A26: 4일차 | B26: =주차별계획!B11&"차시 "&주차별계획!C11 -> 7차시 딕셔너리와 집합 | C26: 4일차 | D26: =주차별계획!B12&"차시 "&주차별계획!C12 -> 8차시 함수 기초
A27: 5일차 | B27: =주차별계획!B13&"차시 "&주차별계획!C13 -> 9차시 함수 심화 | C27: 5일차 | D27: =주차별계획!B14&"차시 "&주차별계획!C14 -> 10차시 모듈과 패키지
A28: 6일차 | B28: =주차별계획!B15&"차시 "&주차별계획!C15 -> 11차시 예외 처리 | C28: 6일차 | D28: =주차별계획!B16&"차시 "&주차별계획!C16 -> 12차시 파일 입출력
A29: 7일차 | B29: =주차별계획!B17&"차시 "&주차별계획!C17 -> 13차시 클래스와 객체 | C29: 7일차 | D29: =주차별계획!B18&"차시 "&주차별계획!C18 -> 14차시 상속과 다형성
A30: 8일차 | B30: =주차별계획!B19&"차시 "&주차별계획!C19 -> 15차시 외부 라이브러리 활용 | C30: 8일차 | D30: =주차별계획!B20&"차시 "&주차별계획!C20 -> 16차시 데이터 처리(pandas 기초)
A31: 9일차 | B31: =주차별계획!B21&"차시 "&주차별계획!C21 -> 17차시 데이터 시각화 | C31: 9일차 | D31: =주차별계획!B22&"차시 "&주차별계획!C22 -> 18차시 미니 프로젝트 기획·설계
A32: 10일차 | B32: =주차별계획!B23&"차시 "&주차별계획!C23 -> 19차시 미니 프로젝트 구현 | C32: 10일차 | D32: =주차별계획!B24&"차시 "&주차별계획!C24 -> 20차시 프로젝트 발표 및 내부평가
A34: 5. 과제·평가·출결 안내
A35: 과제 | B35: 매 차시 실습과제를 LMS에 다음 수업 전까지 제출합니다. 지각 제출은 감점, 미제출은 0점 처리됩니다.
A36: 평가 | B36: =교과개요!B32 -> 형성평가(퀴즈) 10% / 실습과제 30% / 지필평가 20% / 실무평가(프로젝트) 40%
A37: 평가 일정 | B37: 형성평가: 7차시·14차시 수업 중 40분 / 지필·실무평가: 20차시(마지막 날) / 프로젝트 발표: 20차시
A38: 이수 기준 | B38: =교과개요!B33 -> 출석률 80% 이상(과정평가형: 능력단위별 75% 이상) + 모든 내부평가 참여 + 종합 60점 이상. 능력단위별 100점 환산 성적을 별도 산출
A39: 출결 | B39: 수업 시작·종료 시 출결 체크(카드/QR). 지각·조퇴 3회 = 결석 1회. 훈련수당·수료 요건과 직결되므로 사유 발생 시 반드시 사전 연락.
A40: 재평가 | B40: 평가 미참여 또는 기준 미달 시 1회 재평가 기회가 제공됩니다(일정은 별도 안내).
A42: 6. 문의
A43: 강사 | B43: 홍길동 강사 / 슬랙 DM 또는 수업 전후 질의 | C43: 교무/행정 | D43: 코리아AI아카데미 교무팀 02-000-0000
